<mujoco model="hopper">
  <compiler angle="degree" inertiafromgeom="true"/>
  <default>
    <joint armature="1" damping="1" limited="true"/>
    <motor ctrllimited="true" ctrlrange="-.4 .4"/>
  </default>
  <option integrator="RK4" timestep="0.002"/>
  <visual>
    <map znear="0.02"/>
  </visual>

  <asset>
    <texture builtin="flat" height="1278" mark="cross" markrgb="1 1 1" name="texgeom"
      random="0.01" rgb1="0.8 0.6 0.4" rgb2="0.8 0.6 0.4" type="cube" width="127"/>
    <material name="geom" texture="texgeom" texuniform="true"/>
  </asset>

  <worldbody>
    <light cutoff="100" diffuse="1 1 1" dir="0 0 -1.3" directional="true"
      exponent="1" pos="0 0 1.3" specular=".1 .1 .1"/>

    <body name="torso" pos="0 0 1.25">
      <camera name="track" mode="trackcom" pos="0 -3 1" xyaxes="1 0 0 0 0 1"/>
      <joint armature="0" axis="1 0 0" damping="0" limited="false" name="rootx"
        pos="0 0 0" stiffness="0" type="slide"/>
      <joint armature="0" axis="0 0 1" damping="0" limited="false" name="rootz"
        pos="0 0 0" ref="1.25" stiffness="0" type="slide"/>
      <joint armature="0" axis="0 1 0" damping="0" limited="false" name="rooty"
        pos="0 0 0" stiffness="0" type="hinge"/>
      <!-- torso: local coords, center at 0, goes +0.2 up and -0.2 down -->
      <geom friction="0.9" fromto="0 0 0.2 0 0 -0.2" name="torso_geom"
        size="0.05" type="capsule" material="geom"/>

      <body name="thigh" pos="0 0 -0.2">
        <joint axis="0 -1 0" name="thigh_joint" pos="0 0 0" range="-150 0" type="hinge"/>
        <!-- thigh: 0.45m long, goes from 0 down to -0.45 in local coords -->
        <geom friction="0.9" fromto="0 0 0 0 0 -0.45" name="thigh_geom"
          size="0.05" type="capsule" material="geom"/>

        <body name="leg" pos="0 0 -0.45">
          <joint axis="0 -1 0" name="leg_joint" pos="0 0 0" range="-150 0" type="hinge"/>
          <!-- leg: 0.5m long, goes from 0 down to -0.5 in local coords -->
          <geom friction="0.9" fromto="0 0 0 0 0 -0.5" name="leg_geom"
            size="0.04" type="capsule" material="geom"/>

          <body name="foot" pos="0 0 -0.5">
            <joint axis="0 -1 0" name="foot_joint" pos="0 0 0" range="-45 45" type="hinge"/>
            <!-- foot: horizontal capsule -->
            <geom friction="2.0" fromto="-0.13 0 0 0.26 0 0" name="foot_geom"
              size="0.06" type="capsule" material="geom"/>
          </body>
        </body>
      </body>
    </body>
  </worldbody>

  <actuator>
    <motor ctrllimited="true" ctrlrange="-1.0 1.0" gear="200.0" joint="thigh_joint"/>
    <motor ctrllimited="true" ctrlrange="-1.0 1.0" gear="200.0" joint="leg_joint"/>
    <motor ctrllimited="true" ctrlrange="-1.0 1.0" gear="200.0" joint="foot_joint"/>
  </actuator>

</mujoco>